Workbook

Sheet Summary
A1: Excel Data Analysis – Sales Summary (FY2025)
A2: Dataset: Superstore-style retail sales, 600 orders, Jan–Dec 2025 (sample/synthetic data – see README note)
A4: Total Sales | B4: Total Profit | C4: Profit Margin | D4: Total Orders | E4: Avg Order Value
A5: =Working!B5 -> 406636.64 | B5: =Working!B6 -> 17519.75 | C5: =Working!B7 -> 0.043084534 | D5: =Working!B8 -> 600 | E5: =Working!B9 -> 677.72773
A40: KEY FINDINGS
A41: The business generated about 406.6K in sales and 17.5K in profit across 600 orders in 2025, a thin overall margin of 4.3%. Technology is the star category (54% of sales, 14.0% margin), while Furniture contributes 35% of sales but loses money (-11.1% margin, about -15.9K), mainly because of heavy discounting. Orders discounted 30% or more brought in 72K of sales but produced a combined loss of about 14K. East and West lead on sales, whereas the Central region is roughly break-even (-0.5% margin) and South has the best margin (8.9%). Sales peak in Nov-Dec (about 105K together) and March, so inventory and marketing should be planned around those periods. Recommendation: cap discounts on Furniture, push Technology, and review pricing and costs in the Central region.
A50: Note: dataset is sample/synthetic (Superstore-style). To use the real Superstore/Retail dataset, paste it into Raw_Data (same columns) – all tabs recalculate; update this paragraph.

Sheet Raw_Data
A1: Order ID | B1: Order Date | C1: Region | D1: Category | E1: Sub-Category | F1: Segment | G1: Quantity | H1: Sales | I1: Discount | J1: Profit
A2: ORD-2025-0001 | B2: 45660 | C2: South | D2: Office Supplies | E2: Storage | F2: Corporate | G2: 6 | H2: 281.64 | I2: 0.2 | J2: -17.91
A3: ORD-2025-0002 | B3: 45661 | C3: Central | D3: Furniture | E3: Bookcases | F3: Consumer | G3: 5 | H3: 1390.77 | I3: 0.1 | J3: -82.67
A4: ORD-2025-0003 | B4: 45661 | C4: Central | D4: Technology | E4: Phones | F4: Corporate | G4: 3 | H4: 1148.92 | I4: 0 | J4: 144.7
A5: ORD-2025-0004 | B5: 45663 | C5: West | D5: Technology | E5: Phones | F5: Home Office | G5: 7 | H5: 3916.41 | I5: 0.1 | J5: 727.55
A6: ORD-2025-0005 | B6: 45663 | C6: West | D6: Technology | E6: Accessories | F6: Home Office | G6: 1 | H6: 541.38 | I6: 0.1 | J6: 98.75
A7: ORD-2025-0006 | B7: 45664 | C7: East | D7: Office Supplies | E7: Storage | F7: Consumer | G7: 7 | H7: 278.19 | I7: 0.2 | J7: 3.43
A8: ORD-2025-0007 | B8: 45665 | C8: Central | D8: Technology | E8: Copiers | F8: Consumer | G8: 6 | H8: 2043.93 | I8: 0 | J8: 343.31
A9: ORD-2025-0008 | B9: 45666 | C9: West | D9: Furniture | E9: Tables | F9: Corporate | G9: 4 | H9: 999.67 | I9: 0 | J9: -10.58
A10: ORD-2025-0009 | B10: 45668 | C10: South | D10: Office Supplies | E10: Binders | F10: Consumer | G10: 2 | H10: 65.66 | I10: 0.4 | J10: -18.83
A11: ORD-2025-0010 | B11: 45668 | C11: East | D11: Office Supplies | E11: Binders | F11: Home Office | G11: 7 | H11: 189.37 | I11: 0 | J11: 37.16
A12: ORD-2025-0011 | B12: 45669 | C12: South | D12: Office Supplies | E12: Paper | F12: Consumer | G12: 6 | H12: 208.9 | I12: 0.1 | J12: 23.14
A13: ORD-2025-0012 | B13: 45669 | C13: Central | D13: Technology | E13: Phones | F13: Corporate | G13: 1 | H13: 597.98 | I13: 0 | J13: 168.86
... A601: ORD-2025-0600 | B601: 46022 | C601: West | D601: Office Supplies | E601: Binders | F601: Consumer | G601: 5 | H601: 114.9 | I601: 0.3 | J601: -0.94

Sheet Working
A1: Working Tab – SUMIFS / COUNTIFS / AVERAGEIFS (pivot-style tables)
A2: All figures are formulas on Raw_Data using named ranges (Sales, Profit, Region, ...). Change Raw_Data and everything updates.
A4: OVERALL KPIs
A5: Total Sales | B5: =SUM(Sales) -> 406636.64
A6: Total Profit | B6: =SUM(Profit) -> 17519.75
A7: Profit Margin | B7: =B6/B5 -> 0.043084534
A8: Total Orders | B8: =COUNTA(OrderID) -> 600
A9: Avg Order Value | B9: =B5/B8 -> 677.72773
A10: Units Sold | B10: =SUM(Qty) -> 2423
A11: Avg Discount | B11: =AVERAGE(Discount) -> 0.13666667
A13: PIVOT 1 – Sales by Category
A14: Category | B14: Sales | C14: Profit | D14: Profit Margin | E14: Orders | F14: Avg Order Value | G14: Avg Discount | H14: % of Sales
A15: Furniture | B15: =SUMIFS(Sales,Category,$A15) -> 143184.44 | C15: =SUMIFS(Profit,Category,$A15) -> -15860.03 | D15: =IFERROR(C15/B15,0) -> -0.11076644 | E15: =COUNTIFS(Category,$A15) -> 146 | F15: =IFERROR(B15/E15,0) -> 980.71534 | G15: =AVERAGEIFS(Discount,Category,$A15) -> 0.12739726 | H15: =B15/$B$5 -> 0.35211888
A16: Office Supplies | B16: =SUMIFS(Sales,Category,$A16) -> 42325.07 | C16: =SUMIFS(Profit,Category,$A16) -> 2421.93 | D16: =IFERROR(C16/B16,0) -> 0.057222114 | E16: =COUNTIFS(Category,$A16) -> 294 | F16: =IFERROR(B16/E16,0) -> 143.96282 | G16: =AVERAGEIFS(Discount,Category,$A16) -> 0.14761905 | H16: =B16/$B$5 -> 0.10408573
A17: Technology | B17: =SUMIFS(Sales,Category,$A17) -> 221127.13 | C17: =SUMIFS(Profit,Category,$A17) -> 30957.85 | D17: =IFERROR(C17/B17,0) -> 0.14000023 | E17: =COUNTIFS(Category,$A17) -> 160 | F17: =IFERROR(B17/E17,0) -> 1382.0446 | G17: =AVERAGEIFS(Discount,Category,$A17) -> 0.125 | H17: =B17/$B$5 -> 0.54379539
A18: Grand Total | B18: =SUM(B15:B17) -> 406636.64 | C18: =SUM(C15:C17) -> 17519.75 | D18: =C18/B18 -> 0.043084534 | E18: =SUM(E15:E17) -> 600 | F18: =B18/E18 -> 677.72773 | G18: =$B$11 -> 0.13666667 | H18: =SUM(H15:H17) -> 1
A20: PIVOT 2 – Sales by Region
A21: Region | B21: Sales | C21: Profit | D21: Profit Margin | E21: Orders | F21: Avg Order Value | G21: Avg Discount | H21: % of Sales
A22: East | B22: =SUMIFS(Sales,Region,$A22) -> 125751.78 | C22: =SUMIFS(Profit,Region,$A22) -> 4003.02 | D22: =IFERROR(C22/B22,0) -> 0.03183271 | E22: =COUNTIFS(Region,$A22) -> 172 | F22: =IFERROR(B22/E22,0) -> 731.115 | G22: =AVERAGEIFS(Discount,Region,$A22) -> 0.12790698 | H22: =B22/$B$5 -> 0.30924852
A23: West | B23: =SUMIFS(Sales,Region,$A23) -> 122966.83 | C23: =SUMIFS(Profit,Region,$A23) -> 6593.82 | D23: =IFERROR(C23/B23,0) -> 0.053622753 | E23: =COUNTIFS(Region,$A23) -> 196 | F23: =IFERROR(B23/E23,0) -> 627.38179 | G23: =AVERAGEIFS(Discount,Region,$A23) -> 0.13928571 | H23: =B23/$B$5 -> 0.30239978
A24: Central | B24: =SUMIFS(Sales,Region,$A24) -> 76209.37 | C24: =SUMIFS(Profit,Region,$A24) -> -355.3 | D24: =IFERROR(C24/B24,0) -> -0.0046621564 | E24: =COUNTIFS(Region,$A24) -> 119 | F24: =IFERROR(B24/E24,0) -> 640.41487 | G24: =AVERAGEIFS(Discount,Region,$A24) -> 0.15546218 | H24: =B24/$B$5 -> 0.18741393
A25: South | B25: =SUMIFS(Sales,Region,$A25) -> 81708.66 | C25: =SUMIFS(Profit,Region,$A25) -> 7278.21 | D25: =IFERROR(C25/B25,0) -> 0.089075136 | E25: =COUNTIFS(Region,$A25) -> 113 | F25: =IFERROR(B25/E25,0) -> 723.08549 | G25: =AVERAGEIFS(Discount,Region,$A25) -> 0.12566372 | H25: =B25/$B$5 -> 0.20093777
A26: Grand Total | B26: =SUM(B22:B25) -> 406636.64 | C26: =SUM(C22:C25) -> 17519.75 | D26: =C26/B26 -> 0.043084534 | E26: =SUM(E22:E25) -> 600 | F26: =B26/E26 -> 677.72773 | G26: =$B$11 -> 0.13666667 | H26: =SUM(H22:H25) -> 1
A28: PIVOT 3 – Sales by Customer Segment
A29: Segment | B29: Sales | C29: Profit | D29: Profit Margin | E29: Orders | F29: Avg Order Value | G29: Avg Discount | H29: % of Sales
A30: Consumer | B30: =SUMIFS(Sales,Segment,$A30) -> 192371.93 | C30: =SUMIFS(Profit,Segment,$A30) -> 7064.85 | D30: =IFERROR(C30/B30,0) -> 0.036724953 | E30: =COUNTIFS(Segment,$A30) -> 291 | F30: =IFERROR(B30/E30,0) -> 661.07192 | G30: =AVERAGEIFS(Discount,Segment,$A30) -> 0.13264605 | H30: =B30/$B$5 -> 0.47308066
A31: Corporate | B31: =SUMIFS(Sales,Segment,$A31) -> 114808.83 | C31: =SUMIFS(Profit,Segment,$A31) -> 3556 | D31: =IFERROR(C31/B31,0) -> 0.030973227 | E31: =COUNTIFS(Segment,$A31) -> 168 | F31: =IFERROR(B31/E31,0) -> 683.38589 | G31: =AVERAGEIFS(Discount,Segment,$A31) -> 0.14880952 | H31: =B31/$B$5 -> 0.28233764
A32: Home Office | B32: =SUMIFS(Sales,Segment,$A32) -> 99455.88 | C32: =SUMIFS(Profit,Segment,$A32) -> 6898.9 | D32: =IFERROR(C32/B32,0) -> 0.069366437 | E32: =COUNTIFS(Segment,$A32) -> 141 | F32: =IFERROR(B32/E32,0) -> 705.36085 | G32: =AVERAGEIFS(Discount,Segment,$A32) -> 0.13049645 | H32: =B32/$B$5 -> 0.2445817
A33: Grand Total | B33: =SUM(B30:B32) -> 406636.64 | C33: =SUM(C30:C32) -> 17519.75 | D33: =C33/B33 -> 0.043084534 | E33: =SUM(E30:E32) -> 600 | F33: =B33/E33 -> 677.72773 | G33: =$B$11 -> 0.13666667 | H33: =SUM(H30:H32) -> 1
A35: PIVOT 4 – Monthly Sales Trend
A36: Month Start | B36: Sales | C36: Profit | D36: Profit Margin | E36: Orders | F36: MoM Sales Growth
A37: 45658 | B37: =SUMIFS(Sales,OrderDate,">="&$A37,OrderDate,"<"&EDATE($A37,1)) -> 24634.17 | C37: =SUMIFS(Profit,OrderDate,">="&$A37,OrderDate,"<"&EDATE($A37,1)) -> 2080.68 | D37: =IFERROR(C37/B37,0) -> 0.084463166 | E37: =COUNTIFS(OrderDate,">="&$A37,OrderDate,"<"&EDATE($A37,1)) -> 36
A38: 45689 | B38: =SUMIFS(Sales,OrderDate,">="&$A38,OrderDate,"<"&EDATE($A38,1)) -> 24471.73 | C38: =SUMIFS(Profit,OrderDate,">="&$A38,OrderDate,"<"&EDATE($A38,1)) -> 878.65 | D38: =IFERROR(C38/B38,0) -> 0.035904695 | E38: =COUNTIFS(OrderDate,">="&$A38,OrderDate,"<"&EDATE($A38,1)) -> 38 | F38: =IFERROR(B38/B37-1,"") -> -0.0065940927
A39: 45717 | B39: =SUMIFS(Sales,OrderDate,">="&$A39,OrderDate,"<"&EDATE($A39,1)) -> 47503.52 | C39: =SUMIFS(Profit,OrderDate,">="&$A39,OrderDate,"<"&EDATE($A39,1)) -> 2961.66 | D39: =IFERROR(C39/B39,0) -> 0.062346117 | E39: =COUNTIFS(OrderDate,">="&$A39,OrderDate,"<"&EDATE($A39,1)) -> 53 | F39: =IFERROR(B39/B38-1,"") -> 0.94115904
A40: 45748 | B40: =SUMIFS(Sales,OrderDate,">="&$A40,OrderDate,"<"&EDATE($A40,1)) -> 22900.52 | C40: =SUMIFS(Profit,OrderDate,">="&$A40,OrderDate,"<"&EDATE($A40,1)) -> 52.92 | D40: =IFERROR(C40/B40,0) -> 0.0023108646 | E40: =COUNTIFS(OrderDate,">="&$A40,OrderDate,"<"&EDATE($A40,1)) -> 32 | F40: =IFERROR(B40/B39-1,"") -> -0.51791951
A41: 45778 | B41: =SUMIFS(Sales,OrderDate,">="&$A41,OrderDate,"<"&EDATE($A41,1)) -> 40829.01 | C41: =SUMIFS(Profit,OrderDate,">="&$A41,OrderDate,"<"&EDATE($A41,1)) -> 2487.49 | D41: =IFERROR(C41/B41,0) -> 0.060924573 | E41: =COUNTIFS(OrderDate,">="&$A41,OrderDate,"<"&EDATE($A41,1)) -> 49 | F41: =IFERROR(B41/B40-1,"") -> 0.78288572
A42: 45809 | B42: =SUMIFS(Sales,OrderDate,">="&$A42,OrderDate,"<"&EDATE($A42,1)) -> 23750.75 | C42: =SUMIFS(Profit,OrderDate,">="&$A42,OrderDate,"<"&EDATE($A42,1)) -> 1489.42 | D42: =IFERROR(C42/B42,0) -> 0.062710441 | E42: =COUNTIFS(OrderDate,">="&$A42,OrderDate,"<"&EDATE($A42,1)) -> 34 | F42: =IFERROR(B42/B41-1,"") -> -0.41828739
A43: 45839 | B43: =SUMIFS(Sales,OrderDate,">="&$A43,OrderDate,"<"&EDATE($A43,1)) -> 31079.9 | C43: =SUMIFS(Profit,OrderDate,">="&$A43,OrderDate,"<"&EDATE($A43,1)) -> 3008.15 | D43: =IFERROR(C43/B43,0) -> 0.096787634 | E43: =COUNTIFS(OrderDate,">="&$A43,OrderDate,"<"&EDATE($A43,1)) -> 45 | F43: =IFERROR(B43/B42-1,"") -> 0.30858604
A44: 45870 | B44: =SUMIFS(Sales,OrderDate,">="&$A44,OrderDate,"<"&EDATE($A44,1)) -> 24733.3 | C44: =SUMIFS(Profit,OrderDate,">="&$A44,OrderDate,"<"&EDATE($A44,1)) -> 1363.49 | D44: =IFERROR(C44/B44,0) -> 0.055127702 | E44: =COUNTIFS(OrderDate,">="&$A44,OrderDate,"<"&EDATE($A44,1)) -> 43 | F44: =IFERROR(B44/B43-1,"") -> -0.20420272
A45: 45901 | B45: =SUMIFS(Sales,OrderDate,">="&$A45,OrderDate,"<"&EDATE($A45,1)) -> 34010.48 | C45: =SUMIFS(Profit,OrderDate,">="&$A45,OrderDate,"<"&EDATE($A45,1)) -> 1106.74 | D45: =IFERROR(C45/B45,0) -> 0.032541146 | E45: =COUNTIFS(OrderDate,">="&$A45,OrderDate,"<"&EDATE($A45,1)) -> 59 | F45: =IFERROR(B45/B44-1,"") -> 0.37508865
...
